Workbook

Sheet VisionPitts Summary
A1: VisionPitts master data list — summary
A2: Counts update automatically from the 'Data Catalog' sheet (columns O–P). Updated 2026-09-26.
A4: VisionPitts status | B4: Organizers' catalog | C4: Added by VisionPitts | D4: Total
A5: In use | B5: =COUNTIFS('Data Catalog'!$P$2:$P$107,$A5,'Data Catalog'!$O$2:$O$107,"Organizers' catalog") -> 14 | C5: =COUNTIFS('Data Catalog'!$P$2:$P$107,$A5,'Data Catalog'!$O$2:$O$107,"Added by VisionPitts") -> 22 | D5: =SUM(B5:C5) -> 36
A6: Partial | B6: =COUNTIFS('Data Catalog'!$P$2:$P$107,$A6,'Data Catalog'!$O$2:$O$107,"Organizers' catalog") -> 6 | C6: =COUNTIFS('Data Catalog'!$P$2:$P$107,$A6,'Data Catalog'!$O$2:$O$107,"Added by VisionPitts") -> 0 | D6: =SUM(B6:C6) -> 6
A7: On disk (unused) | B7: =COUNTIFS('Data Catalog'!$P$2:$P$107,$A7,'Data Catalog'!$O$2:$O$107,"Organizers' catalog") -> 0 | C7: =COUNTIFS('Data Catalog'!$P$2:$P$107,$A7,'Data Catalog'!$O$2:$O$107,"Added by VisionPitts") -> 1 | D7: =SUM(B7:C7) -> 1
A8: Verified, not ingested | B8: =COUNTIFS('Data Catalog'!$P$2:$P$107,$A8,'Data Catalog'!$O$2:$O$107,"Organizers' catalog") -> 11 | C8: =COUNTIFS('Data Catalog'!$P$2:$P$107,$A8,'Data Catalog'!$O$2:$O$107,"Added by VisionPitts") -> 23 | D8: =SUM(B8:C8) -> 34
A9: Not yet | B9: =COUNTIFS('Data Catalog'!$P$2:$P$107,$A9,'Data Catalog'!$O$2:$O$107,"Organizers' catalog") -> 25 | C9: =COUNTIFS('Data Catalog'!$P$2:$P$107,$A9,'Data Catalog'!$O$2:$O$107,"Added by VisionPitts") -> 0 | D9: =SUM(B9:C9) -> 25
A10: Not relevant | B10: =COUNTIFS('Data Catalog'!$P$2:$P$107,$A10,'Data Catalog'!$O$2:$O$107,"Organizers' catalog") -> 4 | C10: =COUNTIFS('Data Catalog'!$P$2:$P$107,$A10,'Data Catalog'!$O$2:$O$107,"Added by VisionPitts") -> 0 | D10: =SUM(B10:C10) -> 4
A11: Total | B11: =SUM(B5:B10) -> 60 | C11: =SUM(C5:C10) -> 46 | D11: =SUM(D5:D10) -> 106
A13: Share of all sources in use | B13: =IF(D11=0,0,D5/D11) -> 0.33962264
A14: Sources in use or partial | B14: =D5+D6 -> 42
A16: Status key | B16: In use = feeds the dashboard or a built layer · Partial = partly used or a substitute is used · On disk (unused) = downloaded but not used · Verified, not ingested = link checked live 2026-09-24/26, ready for the data terminal · Not yet = not investigated · Not relevant = outside Track 3 scope.
A17: Where detail lives | B17: Pipeline registry: data/sources.md · Built layers: 'VisionPitts Layers' sheet and handoff/web-claude/DELIVERED.md · Discovery (~200 sources): docs/data/discovery/DATA_DISCOVERY.md · Files on disk: handoff/web-claude/INVENTORY.md.
A18: Original file | B18: The organizers' version is preserved at data/raw/AI Hackathon for Housing — Public Data Catalog (original 2026-09-26).xlsx.

Sheet Data Catalog
A1: Priority | B1: Category | C1: Data source | D1: Provider / steward | E1: Provider type | F1: Geographic coverage | G1: Granularity | H1: Access / format | I1: Typical update | J1: Primary hackathon uses | K1: Relevant problem briefs | L1: Likely join key | M1: URL | N1: Caveats / licensing notes | O1: Origin | P1: VisionPitts status | Q1: Local path / output | R1: Vintage in use | S1: Tract-level? | T1: VisionPitts notes
A2: Core | B2: Property & parcels | C2: Allegheny County Property Assessments | D2: Allegheny County / WPRDC | E2: Public | F2: Allegheny County | G2: Parcel | H2: Open download; CSV/API | I2: Daily/periodic | J2: Parcel characteristics, assessed land/building values, exemptions, feasibility screening | K2: Feasibility; Typology & Climate | L2: Block and lot / parcel ID | M2: https://data.wprdc.org/dataset/property-assessments | N2: Assessment fields can be stale or missing; do not treat assessed value as market value. | O2: Organizers' catalog | P2: In use | Q2: data/external/parcels/assessments.csv | R2: 2026 | S2: via parcel join | T2: STORIES/YEARBLT drive 3D building heights (fetch_buildings.py).
A3: Core | B3: Property & parcels | C3: Allegheny County Property Sale Transactions | D3: Allegheny County / WPRDC | E3: Public | F3: Allegheny County | G3: Transaction / parcel | H3: Open download; CSV/API | I3: Daily | J3: Comparable sales, price trends, calibration, neighborhood demand | K3: Feasibility; Observatory | L3: Parcel ID; sale date; deed reference | M3: https://data.wprdc.org/dataset/allegheny-county-property-sale-transactions | N3: Filter using sale-validation codes; many nominal transfers are not arm’s-length sales. | O3: Organizers' catalog | P3: Verified, not ingested | S3: via parcel join | T3: 99,176 arm's-length (VALID SALE) records 2012–2026; P1 price-trend signal.
A4: Core | B4: Property & parcels | C4: Allegheny County Parcel Boundaries | D4: Allegheny County GIS / WPRDC | E4: Public | F4: Allegheny County | G4: Parcel polygon | H4: Open GIS download; GeoJSON/SHP/API | I4: Periodic | J4: Map parcels, calculate lot area, spatially join zoning and hazards | K4: All briefs | L4: Parcel ID | M4: https://data.wprdc.org/dataset/allegheny-county-parcel-boundaries | N4: Geometry and assessment records may update on different schedules; validate parcel IDs. | O4: Organizers' catalog | P4: In use | Q4: data/external/parcels/alleghenycounty_parcels202609.geojson | R4: 2026-09 | S4: via spatial join | T4: Building → parcel → assessment join for heights.
A5: Core | B5: Property & parcels | C5: Allegheny County GIS Open Data Portal | D5: Allegheny County | E5: Public | F5: Allegheny County | G5: Varies: parcel to county | H5: ArcGIS Hub downloads and services | I5: Varies | J5: Discover authoritative county boundaries, land use, infrastructure, hazards, and administrative layers | K5: All briefs | L5: Parcel ID; GEOID; spatial join | M5: https://openac-alcogis.opendata.arcgis.com/ | N5: Portal is a catalog; inspect metadata and update dates for each layer. | O5: Organizers' catalog | P5: Not yet | S5: varies | T5: Catalog portal; individual layers listed separately.
A6: Core | B6: Permits & development | C6: PLI Permits | D6: City of Pittsburgh / WPRDC | E6: Public | F6: City of Pittsburgh | G6: Permit / address | H6: Open download; CSV/GeoJSON/API | I6: Daily | J6: Project pipeline, permit type, status, processing-time analysis | K6: Feasibility; Permit Navigator; Observatory | L6: Address; parcel ID where available; permit ID | M6: https://data.wprdc.org/dataset/pli-permits | N6: Current series begins in 2019; project-level unit counts may require parsing or linkage. | O6: Organizers' catalog | P6: In use | Q6: data/processed/permits.parquet, permits_by_year.parquet | R6: 2019-06 → 2026 | S6: yes (point-in-tract) | T6: D8: new-residential and demolition permits by tract-year; city only; no unit-count field.
A7: Core | B7: Permits & development | C7: Historical PLI Permits | D7: City of Pittsburgh / WPRDC | E7: Public | F7: City of Pittsburgh | G7: Permit / address | H7: Open download; spreadsheet | I7: Historical archive | J7: Long-run permitting trends and before/after policy comparisons | K7: Permit Navigator; Observatory | L7: Address; permit ID | M7: https://data.wprdc.org/dataset/pli-permits | N7: Older records use different schemas and may need normalization. | O7: Organizers' catalog | P7: Not yet | S7: no | T7: Monthly summaries 2015–18 not joinable to tracts.
A8: Core | B8: Permits & development | C8: PLI / DOMI / Environmental Services Violations | D8: City of Pittsburgh / WPRDC | E8: Public | F8: City of Pittsburgh | G8: Violation / address | H8: Open download; CSV/GeoJSON | I8: Daily | J8: Property condition, code-enforcement patterns, completeness and risk flags | K8: Feasibility; Permit Navigator; Observatory | L8: Address; parcel ID where available | M8: https://data.wprdc.org/dataset/pittsburgh-pli-violations-report | N8: Multiple departments share the feed; interpret status and closure fields carefully. | O8: Organizers' catalog | P8: Not yet | S8: via address/parcel
A9: Useful | B9: Permits & development | C9: Condemned and Dead-End Properties | D9: City of Pittsburgh / WPRDC | E9: Public | F9: City of Pittsburgh | G9: Property / address | H9: Open download; CSV/GeoJSON | I9: Frequent | J9: Identify distressed stock, redevelopment candidates, and ownership barriers | K9: Feasibility; Observatory | L9: Address; parcel ID | M9: https://data.wprdc.org/dataset/condemned-properties | N9: Condemnation does not establish demolition feasibility or site availability. | O9: Organizers' catalog | P9: Verified, not ingested | S9: via parcel | T9: Distress signal for 'stabilize failing stock' list (P1).
A10: Core | B10: Zoning & policy | C10: Pittsburgh Zoning Districts | D10: City of Pittsburgh / WPRDC | E10: Public | F10: City of Pittsburgh | G10: Zoning polygon | H10: Open GIS download; CSV/GeoJSON/SHP | I10: Periodic | J10: Determine base zoning and spatially screen allowed development | K10: Feasibility; Permit Navigator; Typology & Climate | L10: Spatial join; zoning code | M10: https://data.wprdc.org/dataset/pittsburgh-zoning | N10: Map alone is insufficient: overlays, definitions, exceptions, and review rules matter. | O10: Organizers' catalog | P10: Verified, not ingested | R10: current (edited 2026-09-22) | S10: via area share | T10: P0: fills 'Can it be built here?'; 1,069 polygons; draft district→typology matrix in docs/data/discovery/01.
A11: Core | B11: Zoning & policy | C11: Pittsburgh Zoning Code | D11: City of Pittsburgh | E11: Public | F11: City of Pittsburgh | G11: Legal text / section | H11: Public website | I11: As amended | J11: Retrieve and cite permitted uses, dimensional standards, parking, reviews, and definitions | K11: Feasibility; Permit Navigator; Typology & Climate | L11: Zoning district; section number | M11: https://pittsburghpa.gov/dcp/zoning-code | N11: Authoritative interpretation belongs to the City; models must cite sections and flag ambiguity. | O11: Organizers' catalog | P11: Partial | Q11: docs/data/discovery/01_land_zoning_development.md | R11: Use Table §911.02 (2024) | S11: n/a | T11: Draft typology permissions with citations; City Zoning Administrator is authoritative. Bill 2025-1545 (ADU by right) pending.
A12: Useful | B12: Zoning & policy | C12: Pittsburgh Zoning Board of Adjustment Decisions | D12: City of Pittsburgh | E12: Public | F12: City of Pittsburgh | G12: Case / parcel / decision | H12: Public agendas, decisions, and records | I12: Ongoing | J12: Train retrieval tools; identify common variances, conditions, and bottlenecks | K12: Feasibility; Permit Navigator | L12: Case number; address; parcel ID | M12: https://pittsburghpa.gov/dcp/zba | N12: Documents may be PDFs and inconsistent over time; outcomes require careful extraction. | O12: Organizers' catalog | P12: Not yet | S12: no
A13: Useful | B13: Zoning & policy | C13: Pennsylvania Municipal Codes | D13: General Code / municipal publishers | E13: Private publisher, public access | F13: Pennsylvania municipalities | G13: Municipal code / section | H13: Public web access | I13: Varies by municipality | J13: Compare zoning and permitting requirements across Allegheny County jurisdictions | K13: Permit Navigator; Typology & Climate | L13: Municipality; chapter; section | M13: https://www.generalcode.com/library/pa | N13: Coverage and update timing vary; some municipalities use other publishers or PDF ordinances. | O13: Organizers' catalog | P13: Not yet | S13: no | T13: No county-wide compiled zoning layer exists; suburbs shown as 'municipal ordinance, not scored'.
A14: Core | B14: Housing production | C14: Pittsburgh Development / Permit Records via OneStopPGH | D14: City of Pittsburgh | E14: Public | F14: City of Pittsburgh | G14: Application / permit / address | H14: Public search portal | I14: Ongoing | J14: Validate current case status and inspect project documents | K14: Feasibility; Permit Navigator; Observatory | L14: Application number; address | M14: https://onestoppgh.pittsburghpa.gov/ | N14: Interactive portal is not necessarily suitable for bulk extraction; respect terms and rate limits. | O14: Organizers' catalog | P14: Not yet | S14: no | T14: Portal; not for bulk extraction.
A15: Useful | B15: Housing production | C15: City-Owned Properties | D15: City of Pittsburgh / WPRDC | E15: Public | F15: City of Pittsburgh | G15: Parcel / property | H15: Open download; CSV/XLSX | I15: Periodic | J15: Public-land pipeline, redevelopment opportunities, disposition analysis | K15: Feasibility; Observatory | L15: Parcel ID; address | M15: https://data.wprdc.org/dataset/city-owned-properties | N15: Ownership and availability are different; verify disposition status. | O15: Organizers' catalog | P15: Verified, not ingested | S15: via parcel | T15: 11,375 City-owned vacant parcels in City parcel layer (P0 land-supply).
A16: Useful | B16: Housing production | C16: City of Pittsburgh Property Tax Abatements | D16: City of Pittsburgh / WPRDC | E16: Public | F16: City of Pittsburgh | G16: Property / abatement | H16: Open download; CSV/XLSX | I16: Periodic | J16: Map incentives, estimate policy reach, link to production outcomes | K16: Feasibility; Observatory | L16: Parcel ID; address | M16: https://data.wprdc.org/dataset/city-of-pittsburgh-property-tax-abatements | N16: Program rules and valuation fields can change; distinguish approval from realized benefit. | O16: Organizers' catalog | P16: Not yet | S16: via parcel
A17: Core | B17: Regional housing needs | C17: Allegheny County Housing Needs Assessment | D17: Allegheny County | E17: Public | F17: Allegheny County; 13 subregions | G17: Subregion / indicator | H17: Public report and data products | I17: Periodic | J17: Baseline needs, affordability, demand, supply gaps, and equity context | K17: Observatory; Typology & Climate | L17: Subregion; municipality | M17: https://www.alleghenycounty.us/Services/Housing/Housing-Needs-Assessment | N17: Useful baseline but too aggregated for parcel-level prototypes; document vintage. | O17: Organizers' catalog | P17: Not yet | S17: no | T17: County's first HNA ordered by Feb 2026 'Housing for All' EO; City HNA 2022 exists.
A18: Core | B18: Demographics & housing | C18: American Community Survey 5-Year | D18: U.S. Census Bureau | E18: Public | F18: United States | G18: Block group, tract, place, county and more | H18: API and downloads | I18: Annual | J18: Income, household size, tenure, rent, value, vacancy, commuting, demographics | K18: Observatory; Typology & Climate | L18: GEOID | M18: https://www.census.gov/data/developers/data-sets/acs-5year.html | N18: Estimates have margins of error; avoid false precision for small areas. | O18: Organizers' catalog | P18: In use | Q18: data/processed/tracts_acs.parquet; profile_change.parquet | R18: 2020–24 and 2009–13 vs 2019–23 | S18: yes | T18: Context stats with MOE/CV; D8 ten-year change with significance flags.
A19: Core | B19: Demographics & housing | C19: Decennial Census | D19: U.S. Census Bureau | E19: Public | F19: United States | G19: Block to nation | H19: API and downloads | I19: Every 10 years | J19: Population, households, occupancy, race/ethnicity, baseline small-area counts | K19: Observatory; Typology & Climate | L19: GEOID | M19: https://www.census.gov/programs-surveys/decennial-census/data.html | N19: Limited socioeconomic detail compared with ACS; geography changes complicate time series. | O19: Organizers' catalog | P19: In use | Q19: data/external/crosswalks/tiger/tl_2020_42_tabblock20.zip | R19: 2020 | S19: yes | T19: Block HOUSING20 for crosswalk weights; DHC H4 renter units for eviction ZIP→tract spread.
A20: Core | B20: Geographic reference | C20: TIGER/Line Shapefiles | D20: U.S. Census Bureau | E20: Public | F20: United States | G20: Blocks, tracts, roads, places and more | H20: Shapefile downloads | I20: Annual | J20: Geographic boundaries and crosswalks for Census and administrative data | K20: All briefs | L20: GEOID | M20: https://www.census.gov/geographies/mapping-files/time-series/geo/tiger-line-file.html | N20: Boundary vintages must match the statistics being joined. | O20: Organizers' catalog | P20: In use | Q20: data/external/boundaries/, tiger_cache/ | R20: 2023 (pinned), 2020, 2010 | S20: yes | T20: Tracts, BGs, places, PUMAs, county subdivisions, ZCTAs.
A21: Core | B21: Affordability | C21: Comprehensive Housing Affordability Strategy (CHAS) | D21: HUD | E21: Public | F21: United States | G21: Custom geography; tract for selected tables | H21: Downloads / query tools | I21: Periodic | J21: Cost burden, housing problems, tenure, household type, and HUD income bands | K21: Observatory; Typology & Climate | L21: GEOID | M21: https://www.huduser.gov/portal/datasets/cp.html | N21: Based on multi-year ACS data; releases lag and tables are complex. | O21: Organizers' catalog | P21: In use | Q21: data/external/benchmark/chas/table8_42003.parquet | R21: 2018–22 | S21: yes | T21: Table 8 → need (renters ≤50% AMI) and cost burden in displacement risk.
A22: Useful | B22: Affordability | C22: Location Affordability Index | D22: HUD / DOT | E22: Public | F22: United States | G22: Block group / tract | H22: Open GIS download | I22: Periodic | J22: Combined housing and transportation cost scenarios | K22: Typology & Climate; Observatory | L22: GEOID | M22: https://hudgis-hud.opendata.arcgis.com/datasets/c1c32742599a42c9a45c95be50ed2ab6_12/about | N22: Modeled estimates depend on household profiles and vintage; not observed household spending. | O22: Organizers' catalog | P22: Not yet | S22: yes | T22: Track 3 core gap (transport cost / carbon story).
A23: Core | B23: Affordability | C23: Fair Market Rents and Small Area FMRs | D23: HUD | E23: Public | F23: United States | G23: Metro / county; ZIP for SAFMR | H23: Downloads / API | I23: Annual | J23: Rent benchmarks, voucher payment standards, preliminary pro formas | K23: Feasibility; Observatory | L23: FIPS; ZIP | M23: https://www.huduser.gov/portal/datasets/fmr.html | N23: Regulatory benchmarks, not direct measures of asking or contract rents. | O23: Organizers' catalog | P23: In use | Q23: web/src/data/income_limits.json | R23: FY2026 | S23: metro | T23: D4: 2BR FMR $1,299 (Pittsburgh HMFA).
A24: Useful | B24: Affordability | C24: HUD Income Limits | D24: HUD | E24: Public | F24: United States | G24: Metro / county / family size | H24: Downloads / API | I24: Annual | J24: Affordable-rent calculations and household eligibility thresholds | K24: Feasibility; Typology & Climate | L24: HUD area; family size | M24: https://www.huduser.gov/portal/datasets/il.html | N24: Use the correct program year and household-size adjustment. | O24: Organizers' catalog | P24: In use | Q24: web/src/data/income_limits.json | R24: FY2026 | S24: metro | T24: D4: 50% AMI $55,200 (family of 4); MFI $110,400.
A25: Core | B25: Subsidized housing | C25: Low-Income Housing Tax Credit Database | D25: HUD | E25: Public | F25: United States | G25: Project / building | H25: Downloadable database and GIS | I25: Periodic | J25: Locate LIHTC stock, placed-in-service dates, units, and preservation needs | K25: Observatory; Typology & Climate | L25: Project ID; address; coordinates | M25: https://www.huduser.gov/portal/datasets/lihtc.html | N25: Some project attributes and geocodes are missing or approximate. | O25: Organizers' catalog | P25: Verified, not ingested | R25: HUD layer (no PIS after 2019) | S25: via point | T25: 215 Allegheny projects, 7,378 LI units; P0 existing affordable stock layer.
A26: Useful | B26: Subsidized housing | C26: National Housing Preservation Database | D26: Public and Affordable Housing Research Corporation / NLIHC | E26: Nonprofit, public registration | F26: United States | G26: Subsidized property | H26: Download after registration | I26: Periodic | J26: Preservation risk, subsidy expirations, affordable housing inventory | K26: Observatory; Typology & Climate | L26: NHPD property ID; address | M26: https://preservationdatabase.org/ | N26: Free access may require registration and agreement to terms. | O26: Organizers' catalog | P26: Not yet | S26: via point | T26: Registration required.
A27: Useful | B27: Vacancy & distress | C27: USPS Vacancy Data | D27: HUD / USPS | E27: Public with conditions | F27: United States | G27: Census tract | H27: Download / mapping tools | I27: Quarterly | J27: Residential vacancy, no-stat addresses, neighborhood distress | K27: Observatory; Typology & Climate | L27: GEOID | M27: https://www.huduser.gov/portal/datasets/usps.html | N27: Aggregated and subject to suppression; “vacant” is a postal-status concept. | O27: Organizers' catalog | P27: Verified, not ingested | R27: 2023 quarterly | S27: yes | T27: WPRDC mirror on 2020 tracts (394/394), no HUD login needed.
A28: Core | B28: Mortgage & finance | C28: Home Mortgage Disclosure Act Data | D28: CFPB / FFIEC | E28: Public | F28: United States | G28: Mortgage application / loan | H28: Bulk download and API | I28: Annual | J28: Loan approvals, denials, borrower characteristics, loan types, lender patterns | K28: Feasibility; Observatory | L28: Census tract GEOID; lender; year | M28: https://ffiec.cfpb.gov/data-publication/ | N28: Protected fields are modified; analysis must be careful about fair-lending interpretation. | O28: Organizers' catalog | P28: Not yet | S28: yes | T28: P1: tract investor share, denial rates.
A29: Useful | B29: Jobs & mobility | C29: LEHD Origin-Destination Employment Statistics (LODES) | D29: U.S. Census Bureau | E29: Public | F29: United States | G29: Census block / flow | H29: Bulk download | I29: Annual | J29: Home-to-work flows, employment access, job density, commute patterns | K29: Observatory; Typology & Climate | L29: Census block GEOID | M29: https://lehd.ces.census.gov/data/ | N29: Data are modeled and noise-infused; latest year lags. | O29: Organizers' catalog | P29: In use | Q29: data/processed/opportunity_access.parquet | R29: LODES8 WAC 2023 | S29: yes (3 km radius) | T29: D2: jobs within 3 km (total, low-wage).
A30: Useful | B30: Jobs & economy | C30: Quarterly Census of Employment and Wages | D30: BLS | E30: Public | F30: United States | G30: County / industry | H30: Downloads and API | I30: Quarterly | J30: Employment and wage trends for demand and feasibility context | K30: Observatory; Typology & Climate | L30: County FIPS; NAICS | M30: https://www.bls.gov/cew/downloadable-data-files.htm | N30: Small cells may be suppressed; workplace location differs from residence. | O30: Organizers' catalog | P30: Not relevant | S30: no | T30: County/industry only.
A31: Useful | B31: Construction costs | C31: Producer Price Index | D31: BLS | E31: Public | F31: United States | G31: National industry / commodity index | H31: API and downloads | I31: Monthly | J31: Construction material and contractor-cost escalation scenarios | K31: Feasibility | L31: Series ID; month | M31: https://www.bls.gov/ppi/data.htm | N31: National indexes are not Pittsburgh bids; use as escalation factors, not level estimates. | O31: Organizers' catalog | P31: Not relevant | S31: no | T31: Construction cost (Track 1).
A32: Core | B32: Transit & accessibility | C32: Pittsburgh Regional Transit GTFS | D32: Pittsburgh Regional Transit / WPRDC | E32: Public | F32: Allegheny County region | G32: Stop, route, trip, schedule | H32: GTFS ZIP / open download | I32: Regular schedule updates | J32: Transit access, service frequency, travel-time and climate scoring | K32: Typology & Climate; Observatory | L32: Stop ID; route ID; spatial join | M32: https://data.wprdc.org/dataset/port-authority-of-allegheny-county-transit-data | N32: Scheduled service is not the same as realized reliability; agency name may appear historically as Port Authority. | O32: Organizers' catalog | P32: In use | Q32: data/external/benchmark/gtfs/prt_gtfs.zip | R32: 2026 feed | S32: yes | T32: transit_access factor: weekday departures ≤400 m per acre.
A33: Useful | B33: Transportation | C33: PennDOT Open Data | D33: PennDOT | E33: Public | F33: Pennsylvania | G33: Road segment, bridge, traffic count | H33: Open GIS and downloads | I33: Varies | J33: Road access, traffic volumes, bridge constraints, crash and infrastructure context | K33: Feasibility; Typology & Climate | L33: Route/segment ID; spatial join | M33: https://gis.penndot.gov/paprojects/ | N33: Different products have different download paths and vintages. | O33: Organizers' catalog | P33: Not yet | S33: no | T33: Low priority for scope.
A34: Useful | B34: Amenities & network | C34: OpenStreetMap | D34: OpenStreetMap contributors | E34: Nonprofit / crowdsourced | F34: Global | G34: Building, road, amenity, address and other features | H34: Open API and extracts | I34: Continuous | J34: Amenities, street network, buildings, walkability proxies, routing | K34: All briefs | L34: OSM ID; spatial join | M34: https://www.openstreetmap.org/ | N34: Completeness varies; comply with ODbL attribution and share-alike requirements. | O34: Organizers' catalog | P34: In use | Q34: data/external/opportunity_access/ (Overpass cache) | R34: OSM 2026-07-28 | S34: yes (800 m radius) | T34: D2 services within 800 m; OpenFreeMap basemap + 3D context; Photon/Nominatim geocoding. Under-maps childcare/pharmacies.
A35: Useful | B35: Address reference | C35: OpenAddresses | D35: Open Knowledge Foundation / contributors | E35: Nonprofit / mixed public sources | F35: Global | G35: Address point | H35: Open bulk download | I35: Varies | J35: Geocoding, address normalization, matching administrative records | K35: All briefs | L35: Normalized address; coordinates | M35: https://openaddresses.io/ | N35: Coverage and licensing vary by source; inspect source metadata. | O35: Organizers' catalog | P35: Not yet | S35: no | T35: Live geocoders used instead.
A36: Core | B36: Topography & imagery | C36: Pennsylvania Spatial Data Access (PASDA) | D36: Penn State Institutes of Energy and the Environment | E36: Public | F36: Pennsylvania | G36: Varies; parcel/vector/raster | H36: Open downloads and map services | I36: Varies | J36: LiDAR, imagery, parcels, mine and environmental layers for site screening | K36: Feasibility; Typology & Climate | L36: Spatial join; parcel ID where present | M36: https://www.pasda.psu.edu/ | N36: Catalog spans many vintages and stewards; inspect each layer’s metadata. | O36: Organizers' catalog | P36: Partial | S36: varies | T36: LiDAR/footprints reviewed; PEMA 2021–23 imagery tiles verified for a satellite toggle.
A37: Core | B37: Topography & imagery | C37: USGS 3D Elevation Program | D37: U.S. Geological Survey | E37: Public | F37: United States | G37: Raster elevation / point cloud | H37: Open download and services | I37: Periodic | J37: Slope, grading difficulty, drainage, viewshed, site constraints | K37: Feasibility; Typology & Climate | L37: Spatial join | M37: https://www.usgs.gov/3d-elevation-program | N37: Resolution and acquisition year vary by location. | O37: Organizers' catalog | P37: In use | Q37: research/musa6950_takeaway/data/dem/; data/processed/tract_terrain.parquet | R37: 1 arc-sec (2024 download) | S37: yes | T37: Tract elevation/slope (info only); Mapterhorn tiles (incl. 3DEP) for 3D terrain.
A38: Useful | B38: Topography & imagery | C38: Allegheny County Orthoimagery | D38: Allegheny County / PASDA | E38: Public | F38: Allegheny County | G38: High-resolution raster tiles | H38: Open download / map service | I38: Periodic flights | J38: Detect structures and land cover; validate parcel and building context | K38: Feasibility; Observatory | L38: Spatial join; tile index | M38: https://www.pasda.psu.edu/uci/SearchResults.aspx?Keyword=Allegheny%20County%20Imagery | N38: Large files; imagery date must be recorded and visual interpretation validated. | O38: Organizers' catalog | P38: Partial | Q38: research/musa6950_takeaway/data/naip/ | R38: NAIP 2022 | S38: yes (zonal) | T38: NAIP used for NDVI vegetation cover instead of county ortho.
A39: Core | B39: Hazards & environment | C39: FEMA National Flood Hazard Layer | D39: FEMA | E39: Public | F39: United States | G39: Flood zone polygon / line | H39: Open GIS services and downloads | I39: Ongoing revisions | J39: Floodplain screening, risk communication, feasibility and climate scoring | K39: Feasibility; Typology & Climate | L39: Spatial join; community/panel ID | M39: https://www.fema.gov/flood-maps/national-flood-hazard-layer | N39: Not a substitute for survey or flood determination; map amendments may matter. | O39: Organizers' catalog | P39: Verified, not ingested | R39: effective 2014-09-26 | S39: via area share | T39: P0: 7,793 Allegheny polygons; validate/replace HAND flood share; streamable raster.
A40: Useful | B40: Hazards & environment | C40: PA DEP eMapPA | D40: Pennsylvania DEP | E40: Public | F40: Pennsylvania | G40: Facility, permit, mine and environmental feature | H40: Interactive map / GIS services | I40: Varies | J40: Contamination, regulated facilities, mining, water and environmental constraints | K40: Feasibility; Typology & Climate | L40: Facility ID; permit ID; spatial join | M40: https://www.dep.pa.gov/DataandTools/Pages/eMapPA.aspx | N40: Multiple programs and vintages; confirm authoritative program records. | O40: Organizers' catalog | P40: Not yet | S40: varies | T40: Mined areas layer noted (1,004 polygons).
...

Sheet Read Me
A1: AI Hackathon for Housing — Public Data Catalog
A3: Purpose | B3: A curated starting point for Pittsburgh and Allegheny County hackathon teams. It prioritizes sources that can support parcel feasibility, permitting, housing-market observatories, typology matching, equity, and climate analysis.
A4: Core vs. Useful | B4: Core sources are likely to support a central prototype workflow. Useful sources add context, validation, or specialized features.
A5: Public does not mean unrestricted | B5: Review the terms, attribution requirements, API limits, and licenses before downloading, redistributing, or publishing derived data.
A6: Private-company public data | B6: Zillow, Redfin, and Realtor.com rows refer to their public aggregate research datasets—not listing-level feeds, property APIs, or permission to scrape their consumer websites.
A7: Geographic joins | B7: Prefer stable identifiers: parcel ID for local property records and Census GEOID/FIPS for statistical geography. Keep a crosswalk when vintages differ.
A8: Quality rule | B8: Record the download date, source vintage, field definitions, missingness, revisions, and any transformations. Never let an AI-generated answer outrank an authoritative rule or source record.
A9: Privacy rule | B9: Do not publish person-level tenant, applicant, mortgage, or household data. Aggregate, suppress small cells, and document consent for contributed data.
A10: VisionPitts master list | B10: Extended by the VisionPitts team (Track 3) on 2026-09-26. The organizers' 60 rows are unchanged in columns A–N. Columns O–T record our status, and rows below the original list are sources VisionPitts added.
A11: VisionPitts columns | B11: Origin · VisionPitts status · Local path / output · Vintage in use · Tract-level? · VisionPitts notes. See the 'VisionPitts Summary' sheet for counts and the status key.

Sheet Brief Source Map
A1: Problem brief | B1: Start with these core sources | C1: High-value additions
A2: Development Feasibility & Pro Forma Navigator | B2: County assessments, sales and parcels; Pittsburgh zoning code/map; PLI permits; OneStopPGH; FEMA flood layer; steep slopes; undermined areas | C2: PASDA/USGS elevation and imagery; BLS PPI; HUD income limits/FMR; Zillow, Redfin and Realtor.com aggregate markets
A3: Policy-to-Permit Navigator | B3: Pittsburgh zoning code; PLI permits; OneStopPGH; ZBA decisions; municipal codes | C3: Violations; condemned properties; cross-jurisdiction county GIS; historical permits
A4: Housing Production, Rents & Household Flow Observatory | B4: PLI permits; ACS; Decennial Census; CHAS; county sales; Zillow ZORI/ZHVI; Redfin; Realtor.com | C4: USPS vacancy; LIHTC/NHPD; HMDA; LODES; Redfin migration; 311
A5: Housing Typology, Equity & Climate Matchmaker | B5: ACS; CHAS; parcels/land use/zoning; PRT GTFS; LAI; FEMA; slopes; ResStock | C5: Opportunity Atlas; EPA EJScreen; NLCD; NOAA; schools; market-demand datasets

Sheet VisionPitts Layers
A1: Layer | B1: File | C1: Roadmap item | D1: Rows | E1: Key columns | F1: Sources | G1: Confidence | H1: How the dashboard uses it | I1: Status
A2: Tract factors (scored) | B2: data/tracts.geojson → web/src/data/tracts.json | C2: Core | D2: 394 | E2: need, market_strength, displacement_risk, subsidy_eligible, transit_access, flood_exposure (+ _conf) | F2: CHAS, MVA, SVI, HCV, QCT/DDA/OZ/CDBG, GTFS, HAND | G2: Per factor | H2: Scoring, map, factor cards | I2: In dashboard
A3: ACS context | B3: data/processed/tracts_acs.parquet | C3: Core | D3: 394 | E3: pop, med_hh_income, med_gross_rent, renter_share, rent_burdened_share (+ CV) | F3: ACS 2020–24 | G3: CV-based | H3: Tract panel 'About this place' | I3: In dashboard
A4: Terrain | B4: data/processed/tract_terrain.parquet | C4: Core | D4: 394 | E4: elev_mean/min/max/range_ft, slope_mean_pct, steep15/25_share | F4: USGS 3DEP | G4: Info only | H4: Terrain card, Elevation/Steep layers | I4: In dashboard
A5: Evictions | B5: data/processed/evictions.parquet | C5: D1 | D5: 394 | E5: eviction_filing_rate, eviction_filing_rate_dhc20, eviction_vs_baseline, evictions_conf | F5: Eviction Lab ETS, Census DHC | G5: Medium/low | H5: Card + map; not yet in displacement_risk (decision pending) | I5: Built, not wired
A6: Market pressure | B6: data/processed/market_pressure.parquet | C6: D3 | D6: 394 | E6: pressure_lag, pressure_class, mva_trend, bivar_class, watch_list, no_rec, lisa_cluster, flip_bal_anti | F6: MVA, CHAS, scoring engine | G6: Low (screening) | H6: One 'Market pressure' map + watch list (58 tracts) | I6: Built, not wired
A7: Income limits & FMR | B7: web/src/data/income_limits.json | C7: D4 | D7: metro | E7: mfi, il30/il50/il80 (1–8 persons), fmr 0–4BR, affordable_rent_50ami | F7: HUD FY2026 | G7: High | H7: Dollar line on landing and tract panel | I7: Built, not wired
A8: Neighborhood change | B8: data/processed/profile_change.parquet | C8: D8 | D8: 394 | E8: <var>_2013/_2023/_chg/_chg_sig for 13 variables | F8: ACS 2009–13, 2019–23, BLS CPI | G8: Medium | H8: 'Ten-year change' section | I8: Built, not wired
A9: Permits & demolitions | B9: data/processed/permits.parquet, permits_by_year.parquet | C9: D8 | D9: 394 | E9: permits_newres_<year>, permits_demo_<year>, totals | F9: City PLI permits | G9: Medium (city only) | H9: Bar chart on tract card | I9: Built, not wired
A10: Opportunity access | B10: data/processed/opportunity_access.parquet | C10: D2 | D10: 394 | E10: jobs_3km_*, school_nearest_*, school_district, svc_*_800m, nearest_supermarket_m | F10: LODES 2023, NCES CCD 2024–25, OSM | G10: Per part | H10: 'Access' section (jobs · schools · services) | I10: Built, not wired
A11: Asking rents | B11: data/processed/asking_rents.parquet + asking_rents_county.json | C11: D7 | D11: 394 | E11: rent_2br_<year>, rent_2br_2025_26, rent_2br_growth_2019_2026, rent_2br_gt_fmr, rent_index_* | F11: Dewey rental listings | G11: High/medium/low by n | H11: Rent card, growth map, FMR gap line | I11: Built, not wired
A12: 3D buildings | B12: data/processed/buildings_focus.geojson → web/src/data/buildings.json | C12: Core | D12: 7,588 bldgs | E12: h, src, yb | F12: Overture, parcels, assessments | G12: 84% heights from records | H12: 3D extrusions in focus tracts | I12: In dashboard
A13: Place search index | B13: data/processed/places.json → web/src/data/places.json | C13: Core | D13: 244 | E13: n, k, c, b, g | F13: WPRDC neighborhoods, Census county subdivisions | G13: n/a | H13: Offline search | I13: In dashboard
